Workbook

Sheet Simulador
A1: COMPRANDO PARA NATAL E TRANSFERINDO PARA PE | R1: PREÇO DE VENDA COM MARGEM DE 25%
A2: Cod | B2: Descrição | C2: NCM | D2: Preço R$/Un | E2: ICMS % | F2: Vlr ICMS | G2: IPI % | H2: Vlr IPI | I2: BC PIS/COFINS | J2: PIS/CONFINS | K2: ST | L2: Vlr ST | M2: Frete CIF ou FOB ? | N2: Frete FOB (10% X Vlr Unit) | O2: Custo filail 4 | P2: Custo Filial 2 | Q2: Custo Filial 3 e 5 | R2: PSD FILIAL 4 (CLIENTE DENTRO DE RN) | S2: PSD FILIAL 4 (CLIENTE FORA DE RN) | T2: PSD FILIAL 3 E 5 (CLIENTE DENTRO DE PE) | U2: PSD FILIAL 2 (CLIENTE FORA DE PE)
B3: DETECTOR DE CALOR ENDEREÇÁVEL WIRELESS DCEW-SKYFIRE | C3: 85311010 | D3: 520.9 | E3: 0.04 | F3: =D3*E3 -> 20.836 | G3: 0.0975 | H3: =D3*G3 -> 50.78775 | I3: =D3*(1-E3) -> 500.064 | J3: =(I3+H3)*9.25% -> 50.953787 | K3: 0 | L3: =D3*K3 -> 0 | M3: FOB | N3: =IF(M3="FOB",(D3+H3)*5%,0) -> 28.584387 | O3: =(D3+H3+L3+N3)-J3 -> 549.31835 | P3: =O3*0.88 -> 483.40015 | Q3: =IF($C3="","",IFERROR($P3*VLOOKUP($C3,'Base Dados NCM'!$A:$G,2,FALSE),"NCM não encontrado")) -> 678.98385 | R3: =IF($C3="","",IFERROR(O3*VLOOKUP($C3,'Base Dados NCM'!$A:$G,6,FALSE),"NCM não encontrado")) -> 950.32075 | S3: =IF($C3="","",IFERROR(O3*VLOOKUP($C3,'Base Dados NCM'!$A:$G,7,FALSE),"NCM não encontrado")) -> 977.78666 | T3: =IF($C3="","",IFERROR(Q3*VLOOKUP($C3,'Base Dados NCM'!$A:$G,4,FALSE),"NCM não encontrado")) -> 1045.6351 | U3: =IF($C3="","",IFERROR(P3*VLOOKUP($C3,'Base Dados NCM'!$A:$G,5,FALSE),"NCM não encontrado")) -> 923.29428
B4: DETECTOR DE FUMAÇA ENDEREÇÁVEL WIRELESS DFEW | C4: 90271000 | D4: 530.8 | E4: 0.04 | F4: =D4*E4 -> 21.232 | G4: 0 | H4: =D4*G4 -> 0 | I4: =D4*(1-E4) -> 509.568 | J4: =(I4+H4)*9.25% -> 47.13504 | K4: 0 | L4: =D4*K4 -> 0 | M4: FOB | N4: =IF(M4="FOB",(D4+H4)*5%,0) -> 26.54 | O4: =(D4+H4+L4+N4)-J4 -> 510.20496 | P4: =O4*0.88 -> 448.98036 | Q4: =IF($C4="","",IFERROR($P4*VLOOKUP($C4,'Base Dados NCM'!$A:$G,2,FALSE),"NCM não encontrado")) -> 448.98036 | R4: =IF($C4="","",IFERROR(O4*VLOOKUP($C4,'Base Dados NCM'!$A:$G,6,FALSE),"NCM não encontrado")) -> 887.75663 | S4: =IF($C4="","",IFERROR(O4*VLOOKUP($C4,'Base Dados NCM'!$A:$G,7,FALSE),"NCM não encontrado")) -> 908.16483 | T4: =IF($C4="","",IFERROR($Q4*VLOOKUP($C4,'Base Dados NCM'!$A:$G,4,FALSE),"NCM não encontrado")) -> 1014.6956 | U4: =IF($C4="","",IFERROR(P4*VLOOKUP($C4,'Base Dados NCM'!$A:$G,5,FALSE),"NCM não encontrado")) -> 857.5525
B5: MODULO DE ENTRADA / SAIDA WIRELESS MEW-SKYFIRE | C5: 85311010 | D5: 645.9 | E5: 0.04 | F5: =D5*E5 -> 25.836 | G5: 0 | H5: =D5*G5 -> 0 | I5: =D5*(1-E5) -> 620.064 | J5: =(I5+H5)*9.25% -> 57.35592 | K5: 0 | L5: =D5*K5 -> 0 | M5: FOB | N5: =IF(M5="FOB",(D5+H5)*5%,0) -> 32.295 | O5: =(D5+H5+L5+N5)-J5 -> 620.83908 | P5: =O5*0.88 -> 546.33839 | Q5: =IF($C5="","",IFERROR($P5*VLOOKUP($C5,'Base Dados NCM'!$A:$G,2,FALSE),"NCM não encontrado")) -> 767.3869 | R5: =IF($C5="","",IFERROR(O5*VLOOKUP($C5,'Base Dados NCM'!$A:$G,6,FALSE),"NCM não encontrado")) -> 1074.0516 | S5: =IF($C5="","",IFERROR(O5*VLOOKUP($C5,'Base Dados NCM'!$A:$G,7,FALSE),"NCM não encontrado")) -> 1105.0936 | T5: =IF($C5="","",IFERROR($Q5*VLOOKUP($C5,'Base Dados NCM'!$A:$G,4,FALSE),"NCM não encontrado")) -> 1181.7758 | U5: =IF($C5="","",IFERROR(P5*VLOOKUP($C5,'Base Dados NCM'!$A:$G,5,FALSE),"NCM não encontrado")) -> 1043.5063
B6: SIRENE AUDIOVISUAL ENDEREÇÁVEL WIRELESS SAVEW-SKYFIRE | C6: 85318000 | D6: 587.7 | E6: 0.04 | F6: =D6*E6 -> 23.508 | G6: 0.0975 | H6: =D6*G6 -> 57.30075 | I6: =D6*(1-E6) -> 564.192 | J6: =(I6+H6)*9.25% -> 57.488079 | K6: 0 | L6: =D6*K6 -> 0 | M6: FOB | N6: =IF(M6="FOB",(D6+H6)*5%,0) -> 32.250038 | O6: =(D6+H6+L6+N6)-J6 -> 619.76271 | P6: =O6*0.88 -> 545.39118 | Q6: =IF($C6="","",IFERROR($P6*VLOOKUP($C6,'Base Dados NCM'!$A:$G,2,FALSE),"NCM não encontrado")) -> 839.90242 | R6: =IF($C6="","",IFERROR(O6*VLOOKUP($C6,'Base Dados NCM'!$A:$G,6,FALSE),"NCM não encontrado")) -> 1072.1895 | S6: =IF($C6="","",IFERROR(O6*VLOOKUP($C6,'Base Dados NCM'!$A:$G,7,FALSE),"NCM não encontrado")) -> 1103.1776 | T6: =IF($C6="","",IFERROR($Q6*VLOOKUP($C6,'Base Dados NCM'!$A:$G,4,FALSE),"NCM não encontrado")) -> 1293.4497 | U6: =IF($C6="","",IFERROR(P6*VLOOKUP($C6,'Base Dados NCM'!$A:$G,5,FALSE),"NCM não encontrado")) -> 1041.6972
B7: DISP. DE PROTEÇÃO CONTRA SURTO (DPS) PARA ALIMENTAÇÃO PRINCIPAL – 220 VCA DPS-22 | C7: 85363090 | D7: 241.07 | E7: 0.07 | F7: =D7*E7 -> 16.8749 | G7: 0 | H7: =D7*G7 -> 0 | I7: =D7*(1-E7) -> 224.1951 | J7: =(I7+H7)*9.25% -> 20.738047 | K7: 0 | L7: =D7*K7 -> 0 | M7: FOB | N7: =IF(M7="FOB",(D7+H7)*5%,0) -> 12.0535 | O7: =(D7+H7+L7+N7)-J7 -> 232.38545 | P7: =O7*0.88 -> 204.4992 | Q7: =IF($C7="","",IFERROR($P7*VLOOKUP($C7,'Base Dados NCM'!$A:$G,2,FALSE),"NCM não encontrado")) -> 274.62197 | R7: =IF($C7="","",IFERROR(O7*VLOOKUP($C7,'Base Dados NCM'!$A:$G,6,FALSE),"NCM não encontrado")) -> 402.02683 | S7: =IF($C7="","",IFERROR(O7*VLOOKUP($C7,'Base Dados NCM'!$A:$G,7,FALSE),"NCM não encontrado")) -> 413.64611 | T7: =IF($C7="","",IFERROR($Q7*VLOOKUP($C7,'Base Dados NCM'!$A:$G,4,FALSE),"NCM não encontrado")) -> 422.91784 | U7: =IF($C7="","",IFERROR(P7*VLOOKUP($C7,'Base Dados NCM'!$A:$G,5,FALSE),"NCM não encontrado")) -> 390.59347
B8: ROTEADOR WIRELESS ROTW-SKYFIRE | C8: 85176241 | D8: 1102.3 | E8: 0.04 | F8: =D8*E8 -> 44.092 | G8: 0.15 | H8: =D8*G8 -> 165.345 | I8: =D8*(1-E8) -> 1058.208 | J8: =(I8+H8)*9.25% -> 113.17865 | K8: 0.045 | L8: =D8*K8 -> 49.6035 | M8: FOB | N8: =IF(M8="FOB",(D8+H8)*5%,0) -> 63.38225 | O8: =(D8+H8+L8+N8)-J8 -> 1267.4521 | P8: =O8*0.88 -> 1115.3578 | Q8: =IF($C8="","",IFERROR($P8*VLOOKUP($C8,'Base Dados NCM'!$A:$G,2,FALSE),"NCM não encontrado")) -> 1115.3578 | R8: =IF($C8="","",IFERROR(O8*VLOOKUP($C8,'Base Dados NCM'!$A:$G,6,FALSE),"NCM não encontrado")) -> 1951.8762 | S8: =IF($C8="","",IFERROR(O8*VLOOKUP($C8,'Base Dados NCM'!$A:$G,7,FALSE),"NCM não encontrado")) -> 2230.7157 | T8: =IF($C8="","",IFERROR($Q8*VLOOKUP($C8,'Base Dados NCM'!$A:$G,4,FALSE),"NCM não encontrado")) -> 1974.1834 | U8: =IF($C8="","",IFERROR(P8*VLOOKUP($C8,'Base Dados NCM'!$A:$G,5,FALSE),"NCM não encontrado")) -> 2487.248
B9: ACIONADOR MANUAL ENDEREÇÁVEL WIRELESS AMEW-SKYFIRE | C9: 85311010 | D9: 669.1 | E9: 0.04 | F9: =D9*E9 -> 26.764 | G9: 0.0975 | H9: =D9*G9 -> 65.23725 | I9: =D9*(1-E9) -> 642.336 | J9: =(I9+H9)*9.25% -> 65.450526 | K9: 0 | L9: =D9*K9 -> 0 | M9: FOB | N9: =IF(M9="FOB",(D9+H9)*5%,0) -> 36.716863 | O9: =(D9+H9+L9+N9)-J9 -> 705.60359 | P9: =O9*0.88 -> 620.93116 | Q9: =IF($C9="","",IFERROR($P9*VLOOKUP($C9,'Base Dados NCM'!$A:$G,2,FALSE),"NCM não encontrado")) -> 872.1599 | R9: =IF($C9="","",IFERROR(O9*VLOOKUP($C9,'Base Dados NCM'!$A:$G,6,FALSE),"NCM não encontrado")) -> 1220.6942 | S9: =IF($C9="","",IFERROR(O9*VLOOKUP($C9,'Base Dados NCM'!$A:$G,7,FALSE),"NCM não encontrado")) -> 1255.9744 | T9: =IF($C9="","",IFERROR($Q9*VLOOKUP($C9,'Base Dados NCM'!$A:$G,4,FALSE),"NCM não encontrado")) -> 1343.1262 | U9: =IF($C9="","",IFERROR(P9*VLOOKUP($C9,'Base Dados NCM'!$A:$G,5,FALSE),"NCM não encontrado")) -> 1185.9785
B10: MÓDULO ISOLADOR DE CURTO CIRCUITO CEW/X ICC-SKYFIRE | C10: 85311010 | D10: 208.1 | E10: 0.04 | F10: =D10*E10 -> 8.324 | G10: 0.0975 | H10: =D10*G10 -> 20.28975 | I10: =D10*(1-E10) -> 199.776 | J10: =(I10+H10)*9.25% -> 20.356082 | K10: 0 | L10: =D10*K10 -> 0 | M10: FOB | N10: =IF(M10="FOB",(D10+H10)*5%,0) -> 11.419488 | O10: =(D10+H10+L10+N10)-J10 -> 219.45316 | P10: =O10*0.88 -> 193.11878 | Q10: =IF($C10="","",IFERROR($P10*VLOOKUP($C10,'Base Dados NCM'!$A:$G,2,FALSE),"NCM não encontrado")) -> 271.25463 | R10: =IF($C10="","",IFERROR(O10*VLOOKUP($C10,'Base Dados NCM'!$A:$G,6,FALSE),"NCM não encontrado")) -> 379.65396 | S10: =IF($C10="","",IFERROR(O10*VLOOKUP($C10,'Base Dados NCM'!$A:$G,7,FALSE),"NCM não encontrado")) -> 390.62662 | T10: =IF($C10="","",IFERROR($Q10*VLOOKUP($C10,'Base Dados NCM'!$A:$G,4,FALSE),"NCM não encontrado")) -> 417.73214 | U10: =IF($C10="","",IFERROR(P10*VLOOKUP($C10,'Base Dados NCM'!$A:$G,5,FALSE),"NCM não encontrado")) -> 368.85686
B11: CENTRAL HÍBRIDA ANALÓGICA COM PLACA DE EXPANSÃO WIRELESS CEW-SKYFIRE-W | C11: 85312000 | D11: 7258.3 | E11: 0.04 | F11: =D11*E11 -> 290.332 | G11: 0.0975 | H11: =D11*G11 -> 707.68425 | I11: =D11*(1-E11) -> 6967.968 | J11: =(I11+H11)*9.25% -> 709.99783 | K11: 0 | L11: =D11*K11 -> 0 | M11: FOB | N11: =IF(M11="FOB",(D11+H11)*5%,0) -> 398.29921 | O11: =(D11+H11+L11+N11)-J11 -> 7654.2856 | P11: =O11*0.88 -> 6735.7714 | Q11: =IF($C11="","",IFERROR($P11*VLOOKUP($C11,'Base Dados NCM'!$A:$G,2,FALSE),"NCM não encontrado")) -> 9244.1726 | R11: =IF($C11="","",IFERROR(O11*VLOOKUP($C11,'Base Dados NCM'!$A:$G,6,FALSE),"NCM não encontrado")) -> 13241.914 | S11: =IF($C11="","",IFERROR(O11*VLOOKUP($C11,'Base Dados NCM'!$A:$G,7,FALSE),"NCM não encontrado")) -> 13624.628 | T11: =IF($C11="","",IFERROR($Q11*VLOOKUP($C11,'Base Dados NCM'!$A:$G,4,FALSE),"NCM não encontrado")) -> 14236.026 | U11: =IF($C11="","",IFERROR(P11*VLOOKUP($C11,'Base Dados NCM'!$A:$G,5,FALSE),"NCM não encontrado")) -> 12865.323
B12: CENTRAL HÍBRIDA ANALÓGICA 750 PONTOS COM PLACA DE EXPANSÃO WIRELESS CEWX-SKYFIRE-W | C12: 85312000 | D12: 13730.9 | E12: 0.04 | F12: =D12*E12 -> 549.236 | G12: 0.0975 | H12: =D12*G12 -> 1338.7628 | I12: =D12*(1-E12) -> 13181.664 | J12: =(I12+H12)*9.25% -> 1343.1395 | K12: 0 | L12: =D12*K12 -> 0 | M12: FOB | N12: =IF(M12="FOB",(D12+H12)*5%,0) -> 753.48314 | O12: =(D12+H12+L12+N12)-J12 -> 14480.006 | P12: =O12*0.88 -> 12742.406 | Q12: =IF($C12="","",IFERROR($P12*VLOOKUP($C12,'Base Dados NCM'!$A:$G,2,FALSE),"NCM não encontrado")) -> 17487.678 | R12: =IF($C12="","",IFERROR(O12*VLOOKUP($C12,'Base Dados NCM'!$A:$G,6,FALSE),"NCM não encontrado")) -> 25050.411 | S12: =IF($C12="","",IFERROR(O12*VLOOKUP($C12,'Base Dados NCM'!$A:$G,7,FALSE),"NCM não encontrado")) -> 25774.411 | T12: =IF($C12="","",IFERROR($Q12*VLOOKUP($C12,'Base Dados NCM'!$A:$G,4,FALSE),"NCM não encontrado")) -> 26931.023 | U12: =IF($C12="","",IFERROR(P12*VLOOKUP($C12,'Base Dados NCM'!$A:$G,5,FALSE),"NCM não encontrado")) -> 24337.995
F13: =D13*E13 -> 0 | H13: =D13*G13 -> 0 | I13: =D13*(1-E13) -> 0 | J13: =(I13+H13)*9.25% -> 0 | K13: 0 | L13: =D13*K13 -> 0 | M13: CIF | N13: =IF(M13="FOB",(D13+H13)*10%,0) -> 0 | O13: =(D13+H13+L13+N13)-J13 -> 0 | P13: =O13*0.88 -> 0 | Q13: =IF($C13="","",IFERROR($P13*VLOOKUP($C13,'Base Dados NCM'!$A:$G,2,FALSE),"NCM não encontrado")) | R13: =IF($C13="","",IFERROR(O13*VLOOKUP($C13,'Base Dados NCM'!$A:$G,6,FALSE),"NCM não encontrado")) | S13: =IF($C13="","",IFERROR(O13*VLOOKUP($C13,'Base Dados NCM'!$A:$G,7,FALSE),"NCM não encontrado")) | T13: =IF($C13="","",IFERROR($Q13*VLOOKUP($C13,'Base Dados NCM'!$A:$G,4,FALSE),"NCM não encontrado")) | U13: =IF($C13="","",IFERROR(P13*VLOOKUP($C13,'Base Dados NCM'!$A:$G,5,FALSE),"NCM não encontrado"))
F14: =D14*E14 -> 0 | G14: 0 | H14: =D14*G14 -> 0 | I14: =D14*(1-E14) -> 0 | J14: =(I14+H14)*9.25% -> 0 | K14: 0 | L14: =D14*K14 -> 0 | M14: CIF | N14: =IF(M14="FOB",D14*10%,0) -> 0 | O14: =(D14+H14+L14+N14)-J14 -> 0 | P14: =O14*0.88 -> 0 | Q14: =IF($C14="","",IFERROR($P14*VLOOKUP($C14,'Base Dados NCM'!$A:$G,2,FALSE),"NCM não encontrado")) | R14: =IF($C14="","",IFERROR(O14*VLOOKUP($C14,'Base Dados NCM'!$A:$G,6,FALSE),"NCM não encontrado")) | S14: =IF($C14="","",IFERROR(O14*VLOOKUP($C14,'Base Dados NCM'!$A:$G,7,FALSE),"NCM não encontrado")) | T14: =IF($C14="","",IFERROR($Q14*VLOOKUP($C14,'Base Dados NCM'!$A:$G,4,FALSE),"NCM não encontrado")) | U14: =IF($C14="","",IFERROR(P14*VLOOKUP($C14,'Base Dados NCM'!$A:$G,5,FALSE),"NCM não encontrado"))
F15: =D15*E15 -> 0 | G15: 0 | H15: =D15*G15 -> 0 | I15: =D15*(1-E15) -> 0 | J15: =(I15+H15)*9.25% -> 0 | K15: 0 | L15: =D15*K15 -> 0 | M15: CIF | N15: =IF(M15="FOB",D15*10%,0) -> 0 | O15: =(D15+H15+L15+N15)-J15 -> 0 | P15: =O15*0.88 -> 0 | Q15: =IF($C15="","",IFERROR($P15*VLOOKUP($C15,'Base Dados NCM'!$A:$G,2,FALSE),"NCM não encontrado")) | R15: =IF($C15="","",IFERROR(O15*VLOOKUP($C15,'Base Dados NCM'!$A:$G,6,FALSE),"NCM não encontrado")) | S15: =IF($C15="","",IFERROR(O15*VLOOKUP($C15,'Base Dados NCM'!$A:$G,7,FALSE),"NCM não encontrado")) | T15: =IF($C15="","",IFERROR($Q15*VLOOKUP($C15,'Base Dados NCM'!$A:$G,4,FALSE),"NCM não encontrado")) | U15: =IF($C15="","",IFERROR(P15*VLOOKUP($C15,'Base Dados NCM'!$A:$G,5,FALSE),"NCM não encontrado"))
F16: =D16*E16 -> 0 | G16: 0 | H16: =D16*G16 -> 0 | I16: =D16*(1-E16) -> 0 | J16: =(I16+H16)*9.25% -> 0 | K16: 0 | L16: =D16*K16 -> 0 | M16: CIF | N16: =IF(M16="FOB",D16*10%,0) -> 0 | O16: =(D16+H16+L16+N16)-J16 -> 0 | P16: =O16*0.88 -> 0 | Q16: =IF($C16="","",IFERROR($P16*VLOOKUP($C16,'Base Dados NCM'!$A:$G,2,FALSE),"NCM não encontrado")) | R16: =IF($C16="","",IFERROR(O16*VLOOKUP($C16,'Base Dados NCM'!$A:$G,6,FALSE),"NCM não encontrado")) | S16: =IF($C16="","",IFERROR(O16*VLOOKUP($C16,'Base Dados NCM'!$A:$G,7,FALSE),"NCM não encontrado")) | T16: =IF($C16="","",IFERROR($Q16*VLOOKUP($C16,'Base Dados NCM'!$A:$G,4,FALSE),"NCM não encontrado")) | U16: =IF($C16="","",IFERROR(P16*VLOOKUP($C16,'Base Dados NCM'!$A:$G,5,FALSE),"NCM não encontrado"))
F17: =D17*E17 -> 0 | G17: 0.065 | H17: =D17*G17 -> 0 | I17: =D17*(1-E17) -> 0 | J17: =(I17+H17)*9.25% -> 0 | K17: 0 | L17: =D17*K17 -> 0 | M17: CIF | N17: =IF(M17="FOB",D17*10%,0) -> 0 | O17: =(D17+H17+L17+N17)-J17 -> 0 | P17: =O17*0.88 -> 0 | Q17: =IF($C17="","",IFERROR($P17*VLOOKUP($C17,'Base Dados NCM'!$A:$G,2,FALSE),"NCM não encontrado")) | R17: =IF($C17="","",IFERROR(O17*VLOOKUP($C17,'Base Dados NCM'!$A:$G,6,FALSE),"NCM não encontrado")) | S17: =IF($C17="","",IFERROR(O17*VLOOKUP($C17,'Base Dados NCM'!$A:$G,7,FALSE),"NCM não encontrado")) | T17: =IF($C17="","",IFERROR($Q17*VLOOKUP($C17,'Base Dados NCM'!$A:$G,4,FALSE),"NCM não encontrado")) | U17: =IF($C17="","",IFERROR(P17*VLOOKUP($C17,'Base Dados NCM'!$A:$G,5,FALSE),"NCM não encontrado"))
F18: =D18*E18 -> 0 | G18: 0.0975 | H18: =D18*G18 -> 0 | I18: =D18*(1-E18) -> 0 | J18: =(I18+H18)*9.25% -> 0 | K18: 0 | L18: =D18*K18 -> 0 | M18: CIF | N18: =IF(M18="FOB",D18*10%,0) -> 0 | O18: =(D18+H18+L18+N18)-J18 -> 0 | P18: =O18*0.88 -> 0 | Q18: =IF($C18="","",IFERROR($P18*VLOOKUP($C18,'Base Dados NCM'!$A:$G,2,FALSE),"NCM não encontrado")) | R18: =IF($C18="","",IFERROR(O18*VLOOKUP($C18,'Base Dados NCM'!$A:$G,6,FALSE),"NCM não encontrado")) | S18: =IF($C18="","",IFERROR(O18*VLOOKUP($C18,'Base Dados NCM'!$A:$G,7,FALSE),"NCM não encontrado")) | T18: =IF($C18="","",IFERROR($Q18*VLOOKUP($C18,'Base Dados NCM'!$A:$G,4,FALSE),"NCM não encontrado")) | U18: =IF($C18="","",IFERROR(P18*VLOOKUP($C18,'Base Dados NCM'!$A:$G,5,FALSE),"NCM não encontrado"))
F19: =D19*E19 -> 0 | G19: 0.0975 | H19: =D19*G19 -> 0 | I19: =D19*(1-E19) -> 0 | J19: =(I19+H19)*9.25% -> 0 | K19: 0 | L19: =D19*K19 -> 0 | M19: CIF | N19: =IF(M19="FOB",D19*10%,0) -> 0 | O19: =(D19+H19+L19+N19)-J19 -> 0 | P19: =O19*0.88 -> 0 | Q19: =IF($C19="","",IFERROR($P19*VLOOKUP($C19,'Base Dados NCM'!$A:$G,2,FALSE),"NCM não encontrado")) | R19: =IF($C19="","",IFERROR(O19*VLOOKUP($C19,'Base Dados NCM'!$A:$G,6,FALSE),"NCM não encontrado")) | S19: =IF($C19="","",IFERROR(O19*VLOOKUP($C19,'Base Dados NCM'!$A:$G,7,FALSE),"NCM não encontrado")) | T19: =IF($C19="","",IFERROR($Q19*VLOOKUP($C19,'Base Dados NCM'!$A:$G,4,FALSE),"NCM não encontrado")) | U19: =IF($C19="","",IFERROR(P19*VLOOKUP($C19,'Base Dados NCM'!$A:$G,5,FALSE),"NCM não encontrado"))
F20: =D20*E20 -> 0 | H20: =D20*G20 -> 0 | I20: =D20*(1-E20) -> 0 | J20: =(I20+H20)*9.25% -> 0 | L20: =D20*K20 -> 0 | N20: =IF(M20="FOB",D20*10%,0) -> 0 | O20: =(D20+H20+L20+N20)-J20 -> 0 | P20: =O20*0.88 -> 0 | Q20: =IF($C20="","",IFERROR($P20*VLOOKUP($C20,'Base Dados NCM'!$A:$G,2,FALSE),"NCM não encontrado")) | R20: =IF($C20="","",IFERROR(O20*VLOOKUP($C20,'Base Dados NCM'!$A:$G,6,FALSE),"NCM não encontrado")) | S20: =IF($C20="","",IFERROR(O20*VLOOKUP($C20,'Base Dados NCM'!$A:$G,7,FALSE),"NCM não encontrado")) | T20: =IF($C20="","",IFERROR($Q20*VLOOKUP($C20,'Base Dados NCM'!$A:$G,4,FALSE),"NCM não encontrado")) | U20: =IF($C20="","",IFERROR(P20*VLOOKUP($C20,'Base Dados NCM'!$A:$G,5,FALSE),"NCM não encontrado"))
F21: =D21*E21 -> 0 | H21: =D21*G21 -> 0 | I21: =D21*(1-E21) -> 0 | J21: =(I21+H21)*9.25% -> 0 | L21: =D21*K21 -> 0 | N21: =IF(M21="FOB",D21*10%,0) -> 0 | O21: =(D21+H21+L21+N21)-J21 -> 0 | P21: =O21*0.88 -> 0 | Q21: =IF($C21="","",IFERROR($P21*VLOOKUP($C21,'Base Dados NCM'!$A:$G,2,FALSE),"NCM não encontrado")) | R21: =IF($C21="","",IFERROR(O21*VLOOKUP($C21,'Base Dados NCM'!$A:$G,6,FALSE),"NCM não encontrado")) | S21: =IF($C21="","",IFERROR(O21*VLOOKUP($C21,'Base Dados NCM'!$A:$G,7,FALSE),"NCM não encontrado")) | T21: =IF($C21="","",IFERROR($Q21*VLOOKUP($C21,'Base Dados NCM'!$A:$G,4,FALSE),"NCM não encontrado")) | U21: =IF($C21="","",IFERROR(P21*VLOOKUP($C21,'Base Dados NCM'!$A:$G,5,FALSE),"NCM não encontrado"))
F22: =D22*E22 -> 0 | H22: =D22*G22 -> 0 | I22: =D22*(1-E22) -> 0 | J22: =(I22+H22)*9.25% -> 0 | L22: =D22*K22 -> 0 | N22: =IF(M22="FOB",D22*10%,0) -> 0 | O22: =(D22+H22+L22+N22)-J22 -> 0 | P22: =O22*0.88 -> 0 | Q22: =IF($C22="","",IFERROR($P22*VLOOKUP($C22,'Base Dados NCM'!$A:$G,2,FALSE),"NCM não encontrado")) | R22: =IF($C22="","",IFERROR(O22*VLOOKUP($C22,'Base Dados NCM'!$A:$G,6,FALSE),"NCM não encontrado")) | S22: =IF($C22="","",IFERROR(O22*VLOOKUP($C22,'Base Dados NCM'!$A:$G,7,FALSE),"NCM não encontrado")) | T22: =IF($C22="","",IFERROR($Q22*VLOOKUP($C22,'Base Dados NCM'!$A:$G,4,FALSE),"NCM não encontrado")) | U22: =IF($C22="","",IFERROR(P22*VLOOKUP($C22,'Base Dados NCM'!$A:$G,5,FALSE),"NCM não encontrado"))
F23: =D23*E23 -> 0 | H23: =D23*G23 -> 0 | I23: =D23*(1-E23) -> 0 | J23: =(I23+H23)*9.25% -> 0 | L23: =D23*K23 -> 0 | N23: =IF(M23="FOB",D23*10%,0) -> 0 | O23: =(D23+H23+L23+N23)-J23 -> 0 | P23: =O23*0.88 -> 0 | Q23: =IF($C23="","",IFERROR($P23*VLOOKUP($C23,'Base Dados NCM'!$A:$G,2,FALSE),"NCM não encontrado")) | R23: =IF($C23="","",IFERROR(O23*VLOOKUP($C23,'Base Dados NCM'!$A:$G,6,FALSE),"NCM não encontrado")) | S23: =IF($C23="","",IFERROR(O23*VLOOKUP($C23,'Base Dados NCM'!$A:$G,7,FALSE),"NCM não encontrado")) | T23: =IF($C23="","",IFERROR($Q23*VLOOKUP($C23,'Base Dados NCM'!$A:$G,4,FALSE),"NCM não encontrado")) | U23: =IF($C23="","",IFERROR(P23*VLOOKUP($C23,'Base Dados NCM'!$A:$G,5,FALSE),"NCM não encontrado"))
F24: =D24*E24 -> 0 | H24: =D24*G24 -> 0 | I24: =D24*(1-E24) -> 0 | J24: =(I24+H24)*9.25% -> 0 | L24: =D24*K24 -> 0 | N24: =IF(M24="FOB",D24*10%,0) -> 0 | O24: =(D24+H24+L24+N24)-J24 -> 0 | P24: =O24*0.88 -> 0 | Q24: =IF($C24="","",IFERROR($P24*VLOOKUP($C24,'Base Dados NCM'!$A:$G,2,FALSE),"NCM não encontrado")) | R24: =IF($C24="","",IFERROR(O24*VLOOKUP($C24,'Base Dados NCM'!$A:$G,6,FALSE),"NCM não encontrado")) | S24: =IF($C24="","",IFERROR(O24*VLOOKUP($C24,'Base Dados NCM'!$A:$G,7,FALSE),"NCM não encontrado")) | T24: =IF($C24="","",IFERROR($Q24*VLOOKUP($C24,'Base Dados NCM'!$A:$G,4,FALSE),"NCM não encontrado")) | U24: =IF($C24="","",IFERROR(P24*VLOOKUP($C24,'Base Dados NCM'!$A:$G,5,FALSE),"NCM não encontrado"))
F25: =D25*E25 -> 0 | H25: =D25*G25 -> 0 | I25: =D25*(1-E25) -> 0 | J25: =(I25+H25)*9.25% -> 0 | L25: =D25*K25 -> 0 | N25: =IF(M25="FOB",D25*10%,0) -> 0 | O25: =(D25+H25+L25+N25)-J25 -> 0 | P25: =O25*0.88 -> 0 | Q25: =IF($C25="","",IFERROR($P25*VLOOKUP($C25,'Base Dados NCM'!$A:$G,2,FALSE),"NCM não encontrado")) | R25: =IF($C25="","",IFERROR(O25*VLOOKUP($C25,'Base Dados NCM'!$A:$G,6,FALSE),"NCM não encontrado")) | S25: =IF($C25="","",IFERROR(O25*VLOOKUP($C25,'Base Dados NCM'!$A:$G,7,FALSE),"NCM não encontrado")) | T25: =IF($C25="","",IFERROR($Q25*VLOOKUP($C25,'Base Dados NCM'!$A:$G,4,FALSE),"NCM não encontrado")) | U25: =IF($C25="","",IFERROR(P25*VLOOKUP($C25,'Base Dados NCM'!$A:$G,5,FALSE),"NCM não encontrado"))
F26: =D26*E26 -> 0 | H26: =D26*G26 -> 0 | I26: =D26*(1-E26) -> 0 | J26: =(I26+H26)*9.25% -> 0 | L26: =D26*K26 -> 0 | N26: =IF(M26="FOB",D26*10%,0) -> 0 | O26: =(D26+H26+L26+N26)-J26 -> 0 | P26: =O26*0.88 -> 0 | Q26: =IF($C26="","",IFERROR($P26*VLOOKUP($C26,'Base Dados NCM'!$A:$G,2,FALSE),"NCM não encontrado")) | R26: =IF($C26="","",IFERROR(O26*VLOOKUP($C26,'Base Dados NCM'!$A:$G,6,FALSE),"NCM não encontrado")) | S26: =IF($C26="","",IFERROR(O26*VLOOKUP($C26,'Base Dados NCM'!$A:$G,7,FALSE),"NCM não encontrado")) | T26: =IF($C26="","",IFERROR($Q26*VLOOKUP($C26,'Base Dados NCM'!$A:$G,4,FALSE),"NCM não encontrado")) | U26: =IF($C26="","",IFERROR(P26*VLOOKUP($C26,'Base Dados NCM'!$A:$G,5,FALSE),"NCM não encontrado"))
F27: =D27*E27 -> 0 | H27: =D27*G27 -> 0 | I27: =D27*(1-E27) -> 0 | J27: =(I27+H27)*9.25% -> 0 | L27: =D27*K27 -> 0 | N27: =IF(M27="FOB",D27*10%,0) -> 0 | O27: =(D27+H27+L27+N27)-J27 -> 0 | P27: =O27*0.88 -> 0 | Q27: =IF($C27="","",IFERROR($P27*VLOOKUP($C27,'Base Dados NCM'!$A:$G,2,FALSE),"NCM não encontrado")) | R27: =IF($C27="","",IFERROR(O27*VLOOKUP($C27,'Base Dados NCM'!$A:$G,6,FALSE),"NCM não encontrado")) | S27: =IF($C27="","",IFERROR(O27*VLOOKUP($C27,'Base Dados NCM'!$A:$G,7,FALSE),"NCM não encontrado")) | T27: =IF($C27="","",IFERROR($Q27*VLOOKUP($C27,'Base Dados NCM'!$A:$G,4,FALSE),"NCM não encontrado")) | U27: =IF($C27="","",IFERROR(P27*VLOOKUP($C27,'Base Dados NCM'!$A:$G,5,FALSE),"NCM não encontrado"))
A32: COMPRANDO DIRETO PARA PE | R32: PREÇO DE VENDA COM MARGEM DE 25% | T32: Simulador 201 | U32: 125 | V32: 65.49
A33: Cod. | B33: Descrição | C33: NCM | D33: Preço R$/Un | E33: ICMS % | F33: Vlr ICMS | G33: IPI % | H33: Vlr IPI | I33: BC PIS/COFINS | J33: PIS/CONFINS | K33: ST | L33: Vlr ST | M33: Frete CIF ou FOB ? | N33: Frete FOB (10% X Vlr Unit) | O33: Custo Filial 4 | P33: Custo Filial 2 | Q33: Custo Filial 3 e 5 | R33: PSD FILIAL 3 E 5 (CLIENTE DENTRO DE PE) | S33: PSD FILIAL 2 (CLIENTE FORA DE PE) | T33: Fator | V33: =U32/V32 -> 1.9086883
A34: 32599 - 32600 | B34: VISION S.4.35 - PAR 8 OHMS - CX A | C34: 85182200 | D34: 129.35 | E34: 0.12 | F34: =D34*E34 -> 15.522 | G34: 0.15 | H34: =D34*G34 -> 19.4025 | I34: =D34*(1-E34) -> 113.828 | J34: =(I34+H34)*9.25% -> 12.323821 | L34: =D34*K34 -> 0 | M34: CIF | N34: =IF(M34="FOB",(D34+H34)*5%,0) -> 0 | O34: =P34*1.12 -> 135.41548 | P34: =(D34+H34+N34)-J34-F34 -> 120.90668 | Q34: =IF($C34="","",IFERROR($P34*VLOOKUP($C34,'Base Dados NCM'!$A:$G,2,FALSE),"NCM não encontrado")) -> 120.90668 | R34: =IF($C34="","",IFERROR($Q34*VLOOKUP($C34,'Base Dados NCM'!$A:$G,4,FALSE),"NCM não encontrado")) -> 273.24909 | S34: =IF($C34="","",IFERROR($P34*VLOOKUP($C34,'Base Dados NCM'!$A:$G,5,FALSE),"NCM não encontrado")) -> 230.93176
A35: 32624 | B35: VISION 50.1.12CX BT - AMPLIFICADOR | C35: 85437019 | D35: 207.5 | E35: 0.12 | F35: =D35*E35 -> 24.9 | G35: 0.065 | H35: =D35*G35 -> 13.4875 | I35: =D35*(1-E35) -> 182.6 | J35: =(I35+H35)*9.25% -> 18.138094 | L35: =D35*K35 -> 0 | M35: CIF | N35: =IF(M35="FOB",(D35+H35)*10%,0) -> 0 | O35: =P35*1.12 -> 199.30334 | P35: =(D35+H35+N35)-J35-F35 -> 177.94941 | Q35: =IF($C35="","",IFERROR($P35*VLOOKUP($C35,'Base Dados NCM'!$A:$G,2,FALSE),"NCM não encontrado")) -> 236.7261 | R35: =IF($C35="","",IFERROR($Q35*VLOOKUP($C35,'Base Dados NCM'!$A:$G,4,FALSE),"NCM não encontrado")) -> 364.55819 | S35: =IF($C35="","",IFERROR($P35*VLOOKUP($C35,'Base Dados NCM'!$A:$G,5,FALSE),"NCM não encontrado")) -> 339.88337
F36: =D36*E36 -> 0 | G36: 0 | H36: =D36*G36 -> 0 | I36: =D36*(1-E36) -> 0 | J36: =(I36+H36)*9.25% -> 0 | L36: =D36*K36 -> 0 | M36: CIF | N36: =IF(M36="FOB",(D36+H36)*10%,0) -> 0 | O36: =P36*1.12 -> 0 | P36: =(D36+H36+N36)-J36-F36 -> 0 | Q36: =IF($C36="","",IFERROR($P36*VLOOKUP($C36,'Base Dados NCM'!$A:$G,2,FALSE),"NCM não encontrado")) | R36: =IF($C36="","",IFERROR($Q36*VLOOKUP($C36,'Base Dados NCM'!$A:$G,4,FALSE),"NCM não encontrado")) | S36: =IF($C36="","",IFERROR($P36*VLOOKUP($C36,'Base Dados NCM'!$A:$G,5,FALSE),"NCM não encontrado"))
F37: =D37*E37 -> 0 | G37: 0 | H37: =D37*G37 -> 0 | I37: =D37*(1-E37) -> 0 | J37: =(I37+H37)*9.25% -> 0 | L37: =D37*K37 -> 0 | M37: CIF | N37: =IF(M37="FOB",(D37+H37)*10%,0) -> 0 | O37: =P37*1.12 -> 0 | P37: =(D37+H37+N37)-J37-F37 -> 0 | Q37: =IF($C37="","",IFERROR($P37*VLOOKUP($C37,'Base Dados NCM'!$A:$G,2,FALSE),"NCM não encontrado")) | R37: =IF($C37="","",IFERROR($Q37*VLOOKUP($C37,'Base Dados NCM'!$A:$G,4,FALSE),"NCM não encontrado")) | S37: =IF($C37="","",IFERROR($P37*VLOOKUP($C37,'Base Dados NCM'!$A:$G,5,FALSE),"NCM não encontrado"))
F38: =D38*E38 -> 0 | G38: 0 | H38: =D38*G38 -> 0 | I38: =D38*(1-E38) -> 0 | J38: =(I38+H38)*9.25% -> 0 | L38: =D38*K38 -> 0 | M38: CIF | N38: =IF(M38="FOB",(D38+H38)*10%,0) -> 0 | O38: =P38*1.12 -> 0 | P38: =(D38+H38+N38)-J38-F38 -> 0 | Q38: =IF($C38="","",IFERROR($P38*VLOOKUP($C38,'Base Dados NCM'!$A:$G,2,FALSE),"NCM não encontrado")) | R38: =IF($C38="","",IFERROR($Q38*VLOOKUP($C38,'Base Dados NCM'!$A:$G,4,FALSE),"NCM não encontrado")) | S38: =IF($C38="","",IFERROR($P38*VLOOKUP($C38,'Base Dados NCM'!$A:$G,5,FALSE),"NCM não encontrado"))
F39: =D39*E39 -> 0 | G39: 0 | H39: =D39*G39 -> 0 | I39: =D39*(1-E39) -> 0 | J39: =(I39+H39)*9.25% -> 0 | L39: =D39*K39 -> 0 | M39: CIF | N39: =IF(M39="FOB",(D39+H39)*10%,0) -> 0 | O39: =P39*1.12 -> 0 | P39: =(D39+H39+N39)-J39-F39 -> 0 | Q39: =IF($C39="","",IFERROR($P39*VLOOKUP($C39,'Base Dados NCM'!$A:$G,2,FALSE),"NCM não encontrado")) | R39: =IF($C39="","",IFERROR($Q39*VLOOKUP($C39,'Base Dados NCM'!$A:$G,4,FALSE),"NCM não encontrado")) | S39: =IF($C39="","",IFERROR($P39*VLOOKUP($C39,'Base Dados NCM'!$A:$G,5,FALSE),"NCM não encontrado"))
F40: =D40*E40 -> 0 | H40: =D40*G40 -> 0 | I40: =D40*(1-E40) -> 0 | J40: =(I40+H40)*9.25% -> 0 | L40: =D40*K40 -> 0 | M40: CIF | N40: =IF(M40="FOB",(D40+H40)*10%,0) -> 0 | O40: =P40*1.12 -> 0 | P40: =(D40+H40+N40)-J40-F40 -> 0 | Q40: =IF($C40="","",IFERROR($P40*VLOOKUP($C40,'Base Dados NCM'!$A:$G,2,FALSE),"NCM não encontrado")) | R40: =IF($C40="","",IFERROR($Q40*VLOOKUP($C40,'Base Dados NCM'!$A:$G,4,FALSE),"NCM não encontrado")) | S40: =IF($C40="","",IFERROR($P40*VLOOKUP($C40,'Base Dados NCM'!$A:$G,5,FALSE),"NCM não encontrado"))
F41: =D41*E41 -> 0 | H41: =D41*G41 -> 0 | I41: =D41*(1-E41) -> 0 | J41: =(I41+H41)*9.25% -> 0 | L41: =D41*K41 -> 0 | M41: CIF | N41: =IF(M41="FOB",(D41+H41)*10%,0) -> 0 | O41: =P41*1.12 -> 0 | P41: =(D41+H41+N41)-J41-F41 -> 0 | Q41: =IF($C41="","",IFERROR($P41*VLOOKUP($C41,'Base Dados NCM'!$A:$G,2,FALSE),"NCM não encontrado")) | R41: =IF($C41="","",IFERROR($Q41*VLOOKUP($C41,'Base Dados NCM'!$A:$G,4,FALSE),"NCM não encontrado")) | S41: =IF($C41="","",IFERROR($P41*VLOOKUP($C41,'Base Dados NCM'!$A:$G,5,FALSE),"NCM não encontrado"))
F42: =D42*E42 -> 0 | H42: =D42*G42 -> 0 | I42: =D42*(1-E42) -> 0 | J42: =(I42+H42)*9.25% -> 0 | L42: =D42*K42 -> 0 | M42: CIF | N42: =IF(M42="FOB",(D42+H42)*10%,0) -> 0 | O42: =P42*1.12 -> 0 | P42: =(D42+H42+N42)-J42-F42 -> 0 | Q42: =IF($C42="","",IFERROR($P42*VLOOKUP($C42,'Base Dados NCM'!$A:$G,2,FALSE),"NCM não encontrado")) | R42: =IF($C42="","",IFERROR($Q42*VLOOKUP($C42,'Base Dados NCM'!$A:$G,4,FALSE),"NCM não encontrado")) | S42: =IF($C42="","",IFERROR($P42*VLOOKUP($C42,'Base Dados NCM'!$A:$G,5,FALSE),"NCM não encontrado"))
F43: =D43*E43 -> 0 | H43: =D43*G43 -> 0 | I43: =D43*(1-E43) -> 0 | J43: =(I43+H43)*9.25% -> 0 | L43: =D43*K43 -> 0 | M43: CIF | N43: =IF(M43="FOB",(D43+H43)*10%,0) -> 0 | O43: =P43*1.12 -> 0 | P43: =(D43+H43+N43)-J43-F43 -> 0 | Q43: =IF($C43="","",IFERROR($P43*VLOOKUP($C43,'Base Dados NCM'!$A:$G,2,FALSE),"NCM não encontrado")) | R43: =IF($C43="","",IFERROR($Q43*VLOOKUP($C43,'Base Dados NCM'!$A:$G,4,FALSE),"NCM não encontrado")) | S43: =IF($C43="","",IFERROR($P43*VLOOKUP($C43,'Base Dados NCM'!$A:$G,5,FALSE),"NCM não encontrado"))
F44: =D44*E44 -> 0 | H44: =D44*G44 -> 0 | I44: =D44*(1-E44) -> 0 | J44: =(I44+H44)*9.25% -> 0 | L44: =D44*K44 -> 0 | M44: CIF | N44: =IF(M44="FOB",(D44+H44)*10%,0) -> 0 | O44: =P44*1.12 -> 0 | P44: =(D44+H44+N44)-J44-F44 -> 0 | Q44: =IF($C44="","",IFERROR($P44*VLOOKUP($C44,'Base Dados NCM'!$A:$G,2,FALSE),"NCM não encontrado")) | R44: =IF($C44="","",IFERROR($Q44*VLOOKUP($C44,'Base Dados NCM'!$A:$G,4,FALSE),"NCM não encontrado")) | S44: =IF($C44="","",IFERROR($P44*VLOOKUP($C44,'Base Dados NCM'!$A:$G,5,FALSE),"NCM não encontrado"))
...

Sheet Base Dados NCM
A1: NCM | B1: FATOR CUSTO FILIAL 3 E 5 | C1: ST | D1: FATOR PSD FILIAL 3 E 5 MARGEM 25% | E1: FATOR PSD FILIAL 2 FORA MARGEM 25% | F1: FATOR PSD FILIAL 4 (CLIENTE DENTRO DE RN) | G1: FATOR PSD FILIAL 4 (CLIENTE FORA DE RN) | H1: ICMS ORIGEM | I1: MVA
A2: 39269090 | B2: 1.2973 | C2: SIM | D2: 1.54 | E2: 1.91 | F2: 1.73 | G2: 1.78
A3: 85177900 | B3: 1.3055 | C3: SIM | D3: 1.54 | E3: 1.91 | F3: 1.73 | G3: 1.78
A4: 73089010 | B4: 1.3383 | C4: SIM | D4: 1.54 | E4: 1.91 | F4: 1.73 | G4: 1.78
A5: 73181600 | B5: 1.3096 | C5: SIM | D5: 1.54 | E5: 1.91 | F5: 1.73 | G5: 1.78
A6: 73182200 | B6: 1.3096 | C6: SIM | D6: 1.54 | E6: 1.91 | F6: 1.73 | G6: 1.78
A7: 73269090 | B7: 1.369 | C7: SIM | D7: 1.54 | E7: 1.91 | F7: 1.73 | G7: 1.78
A8: 85354090 | B8: 1.2993 | C8: SIM | D8: 1.54 | E8: 1.91 | F8: 1.73 | G8: 1.78
A9: 73251000 | B9: 1.45 | C9: SIM | D9: 1.54 | E9: 1.91 | F9: 1.73 | G9: 1.78
A10: 94051190 | B10: 1.3116 | C10: SIM | D10: 1.54 | E10: 1.91 | F10: 1.73 | G10: 1.78
A11: 94054200 | B11: 1.3116 | C11: SIM | D11: 1.54 | E11: 1.91 | F11: 1.73 | G11: 1.78
A12: 85395200 | B12: 1 | C12: NORMAL | D12: 2.26 | E12: 1.91 | F12: 1.74 | G12: 1.78
A13: 85044010 | B13: 1 | C13: NORMAL | D13: 2.26 | E13: 1.91 | F13: 1.74 | G13: 1.78
... A43: 94032090 | B43: 1 | C43: NORMAL | D43: 2.26 | E43: 1.91 | F43: 1.74 | G43: 1.78
A44: 94059900 | B44: 1.3763 | C44: SIM | D44: 1.54 | E44: 1.91 | F44: 1.73 | G44: 1.78 | H44: 0.04 | I44: 0.8355
A45: 85065010 | B45: 1 | C45: NORMAL | D45: 2.26 | E45: 1.91 | F45: 1.74 | G45: 1.78
A46: 85044050 | B46: 1.3075 | C46: SIM | D46: 1.54 | E46: 1.91 | F46: 1.73 | G46: 1.78
A47: 85182100 | B47: 1 | C47: NORMAL | D47: 2.26 | E47: 1.91 | F47: 1.74 | G47: 1.78
A48: 90304090 | B48: 1 | C48: NORMAL | D48: 2.26 | E48: 1.91 | F48: 1.74 | G48: 1.78
A49: 84798999 | B49: 1 | C49: NORMAL | D49: 2.26 | E49: 1.91 | F49: 1.74 | G49: 1.78
A50: 83014000 | B50: 1.3157 | C50: SIM | D50: 1.54 | E50: 1.91 | F50: 1.73 | G50: 1.78
A51: 73063000 | B51: 1 | C51: NORMAL | D51: 2.26 | E51: 1.91 | F51: 1.74 | G51: 1.78
A52: 85437099 | B52: 1 | C52: NORMAL | D52: 2.26 | E52: 1.91 | F52: 1.74 | G52: 1.78
A53: 85369040 | B53: 1.2932 | C53: SIM | D53: 1.54 | E53: 1.91 | F53: 1.73 | G53: 1.78
A54: 85043111 | B54: 1 | C54: NORMAL | D54: 2.26 | E54: 1.91 | F54: 1.74 | G54: 1.78
A55: 85311010 | B55: 1.4046 | C55: SIM | D55: 1.54 | E55: 1.91 | F55: 1.73 | G55: 1.78
A56: 90271000 | B56: 1 | C56: NORMAL | D56: 2.26 | E56: 1.91 | F56: 1.74 | G56: 1.78
... A58: 85182200 | B58: 1 | C58: NORMAL | D58: 2.26 | E58: 1.91 | F58: 1.74 | G58: 1.78

Sheet Base ST RN
A1: NCM | B1: ST
A2: 84715010 | B2: 0.045
A3: 85444200 | B3: 0.045
